Workbook
Name Arm_No: 'Calc.'!#REF!
Name DM_No: 'Calc.'!#REF!
Name Stundensatz: 'Calc.'!$M$1
Name Z_No: 'Calc.'!#REF!

Sheet TW - ASML AVR
J1: -
B2: Repair matrix Double fold (AVR) robots
B3: module_part | C3: id_no | D3: price | E3: need_amount | F3: price_sum
B4: Unit 12NC received: | C4: 4022.480.17075 | F4: upgrade to: 4022.639.49401
B5: Unit serial number: | F5: Repair: 1 ; --
F6: First delivery:
B7: First delivery: 08.06.2019 ; -- | C7: Arm #:
B8: First delivery: 08.06.2019 ; -- | C8: DM #:
B9: First delivery: 08.06.2019 ; -- | C9: Z-stroke #: | F9: Version 08.01.2021 K.Weber
B10: Age dependend parts
B11: Module part | D11: Price | E11: need | F11: sum
B12: Arm parts (after 3,5 years)
B13: Arm - belts incl. Ball-sealings | D13: ='Calc.'!H6 -> 798.122 | F13: =E13*D13 -> 0
B14: Drive module (DM) parts (after 3,5 years)
B15: DM - Lika Motor upgrade (incl. Sealing) | D15: ='Calc.'!H17 -> 6967.222 | F15: =E15*D15 -> 0 | J15: (Motoren, Seals)
B16: Z-stroke module parts (after 5 years)
B17: Z-stroke 14 - average price | D17: ='Calc.'!H31 -> 2739.206 | F17: =E17*D17 -> 0
F18: =SUM(F13:F17) -> 0
B19: Last digit and red mark change dependend parts
B20: Upgrade part | C20: id-no. | F20: sum
B21: Platinepaket to Flex (.4 - .5) | C21: Arm B | D21: ='Calc.'!H42 -> 1102.168 | F21: =E21*D21 -> 0
B22: Lika upgrade from .17075 to .49401 | C22: DM LIKA UPGRADE | D22: ='Calc.'!H47 -> 7536.642 | F22: =E22*D22 -> 0 | J22: (Motoren, Seals, Kabelhaube, Steckerplatte)
F23: =SUM(F21:F22) -> 0
B25: Visual check dependend parts
B26: Module part | D26: Price | F26: sum
B27: Arm
B28: Bearings (Main) | C28: E-10004 | D28: ='Calc.'!H56 -> 602.964 | F28: =E28*D28 -> 0
B29: lower main link | C29: V-700144 | D29: ='Calc.'!I61 -> 1270.4 | F29: =E29*D29 -> 0
B30: second lower link | C30: P2037 | D30: ='Calc.'!I62 -> 972 | F30: =E30*D30 -> 0
B31: upper main link | C31: V-700135 | D31: ='Calc.'!I63 -> 687.6 | F31: =E31*D31 -> 0
B32: second upper link | C32: P2036 | D32: ='Calc.'!I64 -> 539.8 | F32: =E32*D32 -> 0
B33: main connector | C33: 602391 | D33: ='Calc.'!I65 -> 847.2 | F33: =E33*D33 -> 0
B34: moving connector lid | C34: V4004 | D34: ='Calc.'!I66 -> 127.88 | F34: =E34*D34 -> 0
B35: moving connector assy | C35: P2033 | D35: ='Calc.'!I67 -> 423.6 | F35: =E35*D35 -> 0
B36: Polygon bush | C36: V-700144 | D36: ='Calc.'!I68 -> 303 | F36: =E36*D36 -> 0
B37: Arm-gripper interface | C37: V-700133 | D37: ='Calc.'!I69 -> 156.26 | F37: =E37*D37 -> 0
B38: belt-reel upgrade | C38: P2032 | D38: ='Calc.'!I70 -> 1062.756 | F38: =E38*D38 -> 0
B40: Drive module
B41: cable hood | C41: 400370 | D41: ='Calc.'!I84 -> 465.9 | F41: =E41*D41 -> 0
B42: DM housing | C42: 604303 | D42: ='Calc.'!I85 -> 470.38 | F42: =E42*D42 -> 0
...

Sheet Component Costs
B2: Serial No.
A3: Value Arm | B3: ='TW - ASML AVR'!E7 -> 0 | C3: ='Calc.'!#REF! -> #REF!
A5: Value DM | B5: ='TW - ASML AVR'!E8 -> 0 | C5: ='Calc.'!#REF! -> #REF!
A7: Value Z | B7: ='TW - ASML AVR'!E9 -> 0 | C7: ='Calc.'!#REF! -> #REF!
A9: Total : | C9: =SUM(C3:C7) -> #REF!

Sheet History
A1: Version: | B1: Date / KW | C1: Comment: | D1: Name:
A2: a
A3: b | N3: Decisions & Motivation
A4: c
A5: d | N5: # | O5: Decision | P5: Motivation | Q5: By | R5: Date
A6: e | N6: 1 | O6: Max number of repairs on a robot --> 2 (unless completely different cause & repair) | Q6: CaBr | R6: 1148
A7: f | N7: 2 | O7: Max. Age of robot motor (Sc / FA) 3.5 years | P7: Supplier HD has calculated a lifetime of 4 years | Q7: SjVe | R7: 1148
A8: g | N8: 3 | O8: Max repaircost ****% of new price | Q8: JBFH
A9: h | B9: 41961 | C9: Preisanpassung 115/h | D9: P. Jackson | N9: 4
A10: i | B10: 43258 | C10: Neue Matrix-Version (Preise ?) | D10: P. Jackson | N10: 5
A11: J | N11: 6
A12: m | N12: 7 | O12: Preisanpassung 115/h | Q12: PJ | R12: 41961
A13: n | N13: 8
A14: o | N14: 9
A15: p | N15: 10
A16: q
A17: r
A18: s
A19: t | B19: 43348 | C19: 1,4 Zuschlag /90 € Stunde | D19: P. Jackson
A20: u | B20: 44182 | C20: Matrix Lika / DM Preise / Anpassung | D20: P. Jackson

Sheet Calc.
H1: benötigte Zeit | I1: VK in Matrix inkl. Zeit | K1: Stundensatz | L1: 90 | O1: Teil | P1: Material in % | Q1: Service in % | S1: Material | T1: Service | U1: Material | V1: Service | W1: Kontrolle
A2: Bänder inkl. Seals | H2: 4.75 | I2: 880 | K2: Zuschlag | L2: 1.4 | O2: =A2 -> Bänder inkl. Seals | P2: =100/H6*H4 -> 46.43676 | Q2: =100/H6*H5 -> 53.56324 | R2: =Q2+P2 -> 100 | S2: =IF('TW - ASML AVR'!E13<>0,'Calc.'!P2,0) -> 0 | T2: =IF('TW - ASML AVR'!E13<>0,'Calc.'!Q2,0) -> 0 | U2: =S2*H6/100 -> 0 | V2: =T2*H6/100 -> 0 | W2: =V2+U2 -> 0
A3: EINKAUFSPREISE | K3: Kennwort: | L3: Weber
A4: Teil | B4: Bezeichnung | C4: Menge | D4: EK-Preis | E4: Gesamt EK | G4: Material | H4: =SUM(E5:E7)*$L$2 -> 370.622
A5: 602417 | B5: Stahlband gewalzt | C5: 4 | D5: 54.78 | E5: =D5*C5 -> 219.12 | G5: Zeit | H5: =H2*$L$1 -> 427.5
A6: E-11530 | B6: Bal-Seal 100LA-(I)-(24-2)-SP | C6: 2 | D6: 14.99 | E6: =D6*C6 -> 29.98 | G6: Gesamt | H6: =SUM(H4:H5) -> 798.122
A7: E-18076 | B7: Bal-Seal Dichtung | C7: 1 | D7: 15.63 | E7: =D7*C7 -> 15.63
E8: 0
A12: DM - Lika Motor upgrade (incl. Sealing) | H12: 6.5 | I12: 7322.5 | O12: =A12 -> DM - Lika Motor upgrade (incl. Sealing) | P12: =100/H17*H15 -> 91.60354 | Q12: =100/H17*H16 -> 8.3964599 | R12: =Q12+P12 -> 100 | S12: =IF('TW - ASML AVR'!E15<>0,'Calc.'!P12,0) -> 0 | T12: =IF('TW - ASML AVR'!E15<>0,'Calc.'!Q12,0) -> 0 | U12: =S12*H17/100 -> 0 | V12: =T12*H17/100 -> 0 | W12: =V12+U12 -> 0
A13: PREIS Siehe SCARA / SCARA - NT
A14: Teil | B14: Bezeichnung | C14: Menge | D14: EK-Preis | E14: Gesamt EK
A15: E-18076 | B15: Bal-Seal Dichtung | C15: 2 | D15: 15.63 | E15: 31.26 | G15: Material | H15: =SUM(E15:E23)*L2 -> 6382.222
A16: 400127 | B16: Hohlwellenmotor ged. Form | C16: 2 | D16: 1959.72 | E16: 3919.44 | G16: Zeit | H16: 585
A17: E-10109 | B17: Kugellager 61802, Niro | C17: 2 | D17: 16.8 | E17: 33.6 | G17: Gesamt | H17: =SUM(H15:H16) -> 6967.222
A18: 612678 | B18: Lagerplatte | C18: 1 | D18: 48.52 | E18: 48.52
B19: Yen Aufschlag | C19: 2 | D19: 180 | E19: 360
B20: Zusatzkosten Lika | C20: 2 | D20: 46.985714 | E20: 93.971429
B21: Ammortisation | C21: 2 | D21: 205.71429
B22: Sealing | C22: 1 | D22: 71.428571 | E22: 71.428571
A23: E-19572 | B23: Steckerverbinder | C23: 1 | D23: 0.51 | E23: 0.51
A26: Motor/Spindel upgrade - SCARA | F26: Zeit | H26: 8 | I26: 3165 | O26: =A26 -> Motor/Spindel upgrade - SCARA | P26: =100/H31*H29 -> 73.715011 | Q26: =100/H31*H30 -> 26.284989 | R26: =Q26+P26 -> 100 | S26: =IF('TW - ASML AVR'!E17<>0,'Calc.'!P26,0) -> 0 | T26: =IF('TW - ASML AVR'!E17<>0,'Calc.'!Q26,0) -> 0 | U26: =S26*H31/100 -> 0 | V26: =T26*H31/100 -> 0 | W26: =V26+U26 -> 0
A27: EINKAUFSPREISE
A28: Teil | B28: Bezeichnung | C28: Menge | D28: EK-Preis | E28: Gesamt EK
A29: E-10016 | B29: Gewinderollenschraubtrieb | C29: 1 | D29: 770 | E29: =D29*C29 -> 770 | G29: Material | H29: =SUM(E29:E36)*$L$2 -> 2019.206
A30: E-10018 | B30: DC-Micromotor m. | C30: 1 | D30: 350.5 | E30: =D30*C30 -> 350.5 | G30: Zeit | H30: =H26*$L$1 -> 720
A31: E-10052 | B31: Axial-Schrägkugellager | C31: 1 | D31: 144.4 | E31: =D31*C31 -> 144.4 | G31: Gesamt | H31: =SUM(H29:H30) -> 2739.206
A32: E-10057 | B32: Sensor, induktiv | C32: 1 | D32: 18.36 | E32: =D32*C32 -> 18.36
A33: 609808 | B33: Führungswelle Durchm. | C33: 1 | D33: 47.1 | E33: =D33*C33 -> 47.1
A34: E-10051 | B34: Metallbalgkupplung | C34: 1 | D34: 14.36 | E34: =D34*C34 -> 14.36
A35: E-10041 | B35: Permanentmagnet- | C35: 1 | D35: 97.57 | E35: =D35*C35 -> 97.57
H38: 7.5 | I38: 1251.47 | O38: =A39 -> Platinenpaket 4-> 5 | P38: =100/H42*H40 -> 38.757068 | Q38: =100/H42*H41 -> 61.242932 | R38: =Q38+P38 -> 100 | S38: =IF('TW - ASML AVR'!E21<>0,'Calc.'!P38,0) -> 0 | T38: =IF('TW - ASML AVR'!E21<>0,'Calc.'!Q38,0) -> 0 | U38: =S38*H42/100 -> 0 | V38: =T38*H42/100 -> 0 | W38: =V38+U38 -> 0
A39: Platinenpaket 4-> 5
A40: EINKAUFSPREISE | G40: Material | H40: =SUM(E41:E42)*$L$2 -> 427.168
A41: A-607084 | B41: Umbausatz Faltarm | C41: 1 | D41: 305.12 | E41: =D41*C41 -> 305.12 | G41: Zeit | H41: =H38*$L$1 -> 675
G42: Gesamt | H42: =SUM(H40:H41) -> 1102.168
A44: Upgrade auf Lika (Motoren +Kabelhaube+Steckerplatte) | F44: Zeit | O44: Upgrade auf Lika (Motoren +Kabelhaube+Steckerplatte) | P44: =100/H47*H45 -> 90.446674 | Q44: =100/H47*H46 -> 9.5533263 | R44: =Q44+P44 -> 100 | S44: =IF('TW - ASML AVR'!E22<>0,'Calc.'!P44,0) -> 0 | T44: =IF('TW - ASML AVR'!E22<>0,'Calc.'!Q44,0) -> 0 | U44: =S44*H47/100 -> 0 | V44: =T44*H47/100 -> 0 | W44: =V44+U44 -> 0
A45: EINKAUFSPREISE | G45: Material | H45: =SUM(C47:C49) -> 6816.642
C46: Material+Zuschlag | D46: Zeit | E46: Gesamt | G46: Zeit | H46: =SUM(D47:D49) -> 720
A47: Motoren mit zubehör -> siehe H17 | C47: =H15 -> 6382.222 | D47: =H16 -> 585 | E47: =H17 -> 6967.222 | G47: Gesamt | H47: =SUM(H45:H46) -> 7536.642
A48: Kablehaube -> siehe H84 | C48: =F84 -> 375.9 | D48: =H84 -> 90 | E48: =I84 -> 465.9
...

Sheet INTERNAL DOCUMENT
